Traceback (most recent call last):
  File "/home/matthias/anaconda3/lib/python3.9/site-packages/jupyter_cache/executors/utils.py", line 51, in single_nb_execution
    executenb(
  File "/home/matthias/anaconda3/lib/python3.9/site-packages/nbclient/client.py", line 1112, in execute
    return NotebookClient(nb=nb, resources=resources, km=km, **kwargs).execute()
  File "/home/matthias/anaconda3/lib/python3.9/site-packages/nbclient/util.py", line 74, in wrapped
    return just_run(coro(*args, **kwargs))
  File "/home/matthias/anaconda3/lib/python3.9/site-packages/nbclient/util.py", line 53, in just_run
    return loop.run_until_complete(coro)
  File "/home/matthias/anaconda3/lib/python3.9/asyncio/base_events.py", line 642, in run_until_complete
    return future.result()
  File "/home/matthias/anaconda3/lib/python3.9/site-packages/nbclient/client.py", line 553, in async_execute
    await self.async_execute_cell(
  File "/home/matthias/anaconda3/lib/python3.9/site-packages/nbclient/client.py", line 857, in async_execute_cell
    self._check_raise_for_error(cell, exec_reply)
  File "/home/matthias/anaconda3/lib/python3.9/site-packages/nbclient/client.py", line 760, in _check_raise_for_error
    raise CellExecutionError.from_cell_and_msg(cell, exec_reply_content)
nbclient.exceptions.CellExecutionError: An error occurred while executing the following cell:
------------------
dxdy = toDisk.loc[:,[('B(P=2)','bandwidth [GB/s]'),
                     ('B(P=3)','bandwidth [GB/s]'),
                     ('B(P=4)','bandwidth [GB/s]'),
                     ('B(P=5)','bandwidth [GB/s]'),
                     ('B(P=2)','$T_{lat}(1)$ [$\mu$s]'),
                     ('B(P=2)','$T_{lat}(4)$ [$\mu$s]'),
                    ]]

dxdy.columns.set_levels(['B(P=2) [GB/s]','B(P=3) [GB/s]','B(P=4) [GB/s]','B(P=5) [GB/s]',
                         '$T_{lat}(1)$ [$\mu$s]','$T_{lat}(4)$ [$\mu$s]'],level=1,inplace=True)
dxdy.columns.set_labels([0,1,2,3,4,5],level=1,inplace=True)
dxdy.columns=dxdy.columns.droplevel(0)
filename='dxdy.tex'
with open(filename, 'wb') as f:
    f.write(bytes(dxdy.to_latex(
        escape=False,
        column_format='lp{1.5cm}p{1.5cm}p{1.5cm}p{1.5cm}p{1.2cm}p{1.2cm}',
        bold_rows=True),'UTF-8'))
dxdy
------------------

[0;31m---------------------------------------------------------------------------[0m
[0;31mAttributeError[0m                            Traceback (most recent call last)
[0;32m/tmp/ipykernel_8265/992733757.py[0m in [0;36m<module>[0;34m[0m
[1;32m      9[0m dxdy.columns.set_levels(['B(P=2) [GB/s]','B(P=3) [GB/s]','B(P=4) [GB/s]','B(P=5) [GB/s]',
[1;32m     10[0m                          '$T_{lat}(1)$ [$\mu$s]','$T_{lat}(4)$ [$\mu$s]'],level=1,inplace=True)
[0;32m---> 11[0;31m [0mdxdy[0m[0;34m.[0m[0mcolumns[0m[0;34m.[0m[0mset_labels[0m[0;34m([0m[0;34m[[0m[0;36m0[0m[0;34m,[0m[0;36m1[0m[0;34m,[0m[0;36m2[0m[0;34m,[0m[0;36m3[0m[0;34m,[0m[0;36m4[0m[0;34m,[0m[0;36m5[0m[0;34m][0m[0;34m,[0m[0mlevel[0m[0;34m=[0m[0;36m1[0m[0;34m,[0m[0minplace[0m[0;34m=[0m[0;32mTrue[0m[0;34m)[0m[0;34m[0m[0;34m[0m[0m
[0m[1;32m     12[0m [0mdxdy[0m[0;34m.[0m[0mcolumns[0m[0;34m=[0m[0mdxdy[0m[0;34m.[0m[0mcolumns[0m[0;34m.[0m[0mdroplevel[0m[0;34m([0m[0;36m0[0m[0;34m)[0m[0;34m[0m[0;34m[0m[0m
[1;32m     13[0m [0mfilename[0m[0;34m=[0m[0;34m'dxdy.tex'[0m[0;34m[0m[0;34m[0m[0m

[0;31mAttributeError[0m: 'MultiIndex' object has no attribute 'set_labels'
AttributeError: 'MultiIndex' object has no attribute 'set_labels'

